2019-11-04T15:15:57 (16) created PID file '/data/zeoserver/zeoserver.pid'
2019-11-04T15:15:57 (16) opening storage u'1' using FileStorage
2019-11-04T15:15:57 (16) Blob directory /data/blobstorage does not exist. Selected `bushy` layout. 
2019-11-04T15:15:57 (16) Blob directory '/data/blobstorage/' does not exist. Created new directory.
2019-11-04T15:15:57 (16) Blob temporary directory '/data/blobstorage/tmp' does not exist. Created new directory.
2019-11-04T15:15:57 StorageServer created RW with storages: 1:RW:/data/filestorage/Data.fs
2019-11-04T15:15:57 listening on ('', 8080)
2019-11-04T15:16:03 Connected server protocol
2019-11-04T15:16:03 received handshake 'Z5'
2019-11-04T15:16:57 Connected server protocol
2019-11-04T15:16:57 (unconnected) disconnected
2019-11-04T15:17:57 Connected server protocol
2019-11-04T15:17:57 (unconnected) disconnected
2019-11-04T15:18:34 (:8080) disconnected
2019-11-04T15:18:58 (17) created PID file '/data/zeoserver/zeoserver.pid'
2019-11-04T15:18:58 (17) opening storage u'1' using FileStorage
2019-11-04T15:18:58 Ignoring index for /data/filestorage/Data.fs
2019-11-04T15:18:58 StorageServer created RW with storages: 1:RW:/data/filestorage/Data.fs
2019-11-04T15:18:58 listening on ('', 8080)
2019-11-04T15:19:03 Connected server protocol
2019-11-04T15:19:03 received handshake 'Z5'
2019-11-04T15:19:36 Unexpected error while trying to resolve conflict on <ZODB.ConflictResolution.BadClass object at 0x7fbd0226b310>
Traceback (most recent call last):
  File "/plone/buildout-cache/eggs/ZODB-5.5.1-py2.7.egg/ZODB/ConflictResolution.py", line 259, in tryToResolveConflict
    inst = klass.__new__(klass, *newargs)
TypeError: object.__new__(X): X is not a type object (BadClass)
2019-11-04T15:19:36 Bad request, 'vote'
Traceback (most recent call last):
  File "/plone/buildout-cache/eggs/ZEO-5.2.1-py2.7.egg/ZEO/asyncio/server.py", line 103, in message_received
    result = getattr(self.zeo_storage, name)(*args)
  File "/plone/buildout-cache/eggs/ZEO-5.2.1-py2.7.egg/ZEO/StorageServer.py", line 371, in vote
    return self.lock_manager.lock(self, self._vote)
  File "/plone/buildout-cache/eggs/ZEO-5.2.1-py2.7.egg/ZEO/StorageServer.py", line 1166, in lock
    result = func()
  File "/plone/buildout-cache/eggs/ZEO-5.2.1-py2.7.egg/ZEO/StorageServer.py", line 392, in _vote
    getattr(self, op)(*args)
  File "/plone/buildout-cache/eggs/ZEO-5.2.1-py2.7.egg/ZEO/StorageServer.py", line 526, in _store
    self.storage.store(oid, serial, data, '', self.transaction)
  File "/plone/buildout-cache/eggs/ZODB-5.5.1-py2.7.egg/ZODB/FileStorage/FileStorage.py", line 603, in store
    oldserial, data)
  File "/plone/buildout-cache/eggs/ZODB-5.5.1-py2.7.egg/ZODB/ConflictResolution.py", line 297, in tryToResolveConflict
    data=newpickle)
ConflictError: database conflict error (oid 0x01, class OFS.Application.Application, serial this txn started with 0x03d39378a3f15666 2019-11-04 14:16:38.424076, serial currently committed 0x03d3937b91b89622 2019-11-04 14:19:34.153369)
2019-11-04T15:19:36 (:8080) no current transaction: tpc_abort()
2019-11-04T15:19:57 Connected server protocol
2019-11-04T15:19:57 (unconnected) disconnected
2019-11-04T15:20:19 Unexpected error while trying to resolve conflict on <ZODB.ConflictResolution.BadClass object at 0x7fbd01df9f90>
Traceback (most recent call last):
  File "/plone/buildout-cache/eggs/ZODB-5.5.1-py2.7.egg/ZODB/ConflictResolution.py", line 259, in tryToResolveConflict
    inst = klass.__new__(klass, *newargs)
TypeError: object.__new__(X): X is not a type object (BadClass)
2019-11-04T15:20:19 Bad request, 'vote'
Traceback (most recent call last):
  File "/plone/buildout-cache/eggs/ZEO-5.2.1-py2.7.egg/ZEO/asyncio/server.py", line 103, in message_received
    result = getattr(self.zeo_storage, name)(*args)
  File "/plone/buildout-cache/eggs/ZEO-5.2.1-py2.7.egg/ZEO/StorageServer.py", line 371, in vote
    return self.lock_manager.lock(self, self._vote)
  File "/plone/buildout-cache/eggs/ZEO-5.2.1-py2.7.egg/ZEO/StorageServer.py", line 1166, in lock
    result = func()
  File "/plone/buildout-cache/eggs/ZEO-5.2.1-py2.7.egg/ZEO/StorageServer.py", line 392, in _vote
    getattr(self, op)(*args)
  File "/plone/buildout-cache/eggs/ZEO-5.2.1-py2.7.egg/ZEO/StorageServer.py", line 526, in _store
    self.storage.store(oid, serial, data, '', self.transaction)
  File "/plone/buildout-cache/eggs/ZODB-5.5.1-py2.7.egg/ZODB/FileStorage/FileStorage.py", line 603, in store
    oldserial, data)
  File "/plone/buildout-cache/eggs/ZODB-5.5.1-py2.7.egg/ZODB/ConflictResolution.py", line 297, in tryToResolveConflict
    data=newpickle)
ConflictError: database conflict error (oid 0x11, class Products.PluggableAuthService.PluggableAuthService.PluggableAuthService, serial this txn started with 0x03d3937b91b89622 2019-11-04 14:19:34.153369, serial currently committed 0x03d3937c48a0bf77 2019-11-04 14:20:17.022169)
2019-11-04T15:20:19 (:8080) no current transaction: tpc_abort()
2019-11-04T15:20:58 Connected server protocol
2019-11-04T15:20:58 (unconnected) disconnected
2019-11-04T15:21:58 Connected server protocol
2019-11-04T15:21:58 (unconnected) disconnected
2019-11-04T15:22:58 Connected server protocol
2019-11-04T15:22:58 (unconnected) disconnected
2019-11-04T15:23:58 Connected server protocol
2019-11-04T15:23:58 (unconnected) disconnected
2019-11-04T15:24:59 Connected server protocol
2019-11-04T15:24:59 (unconnected) disconnected
2019-11-04T15:25:59 Connected server protocol
2019-11-04T15:25:59 (unconnected) disconnected
2019-11-04T15:26:59 Connected server protocol
2019-11-04T15:26:59 (unconnected) disconnected
2019-11-04T15:28:00 Connected server protocol
2019-11-04T15:28:00 (unconnected) disconnected
2019-11-04T15:29:00 Connected server protocol
2019-11-04T15:29:00 (unconnected) disconnected
2019-11-04T15:30:00 Connected server protocol
2019-11-04T15:30:00 (unconnected) disconnected
